Workbook

Sheet Decision summary
A1: Decision summary
A2: Upshift — Business Plan · Main Scenario
A4: Variable / dimension | B4: Value
A5: Operating break-even month | B5: =MIN('Model inputs'!D48,'Model inputs'!E48,'Model inputs'!F48,'Model inputs'!G48,'Model inputs'!H48,'Model inputs'!I48,'Model inputs'!J48,'Model inputs'!K48,'Model inputs'!L48,'Model inputs'!M48,'Model inputs'!N48,'Model inputs'!O48,'Model inputs'!P48,'Model inputs'!Q48,'Model inputs'!R48,'Model inputs'!S48,'Model inputs'!T48,'Model inputs'!U48,'Model inputs'!V48,'Model inputs'!W48,'Model inputs'!X48,'Model inputs'!Y48,'Model inputs'!Z48,'Model inputs'!B48) -> 46327
A6: Cash break-even month | B6: =MIN('Model inputs'!D13,'Model inputs'!E13,'Model inputs'!F13,'Model inputs'!G13,'Model inputs'!H13,'Model inputs'!I13,'Model inputs'!J13,'Model inputs'!K13,'Model inputs'!L13,'Model inputs'!M13,'Model inputs'!N13,'Model inputs'!O13,'Model inputs'!P13,'Model inputs'!Q13,'Model inputs'!R13,'Model inputs'!S13,'Model inputs'!T13,'Model inputs'!U13,'Model inputs'!V13,'Model inputs'!W13,'Model inputs'!X13,'Model inputs'!Y13,'Model inputs'!Z13,'Model inputs'!B13) -> 46327
A7: Founder investment recovered month | B7: =MIN('Model inputs'!D35,'Model inputs'!E35,'Model inputs'!F35,'Model inputs'!G35,'Model inputs'!H35,'Model inputs'!I35,'Model inputs'!J35,'Model inputs'!K35,'Model inputs'!L35,'Model inputs'!M35,'Model inputs'!N35,'Model inputs'!O35,'Model inputs'!P35,'Model inputs'!Q35,'Model inputs'!R35,'Model inputs'!S35,'Model inputs'!T35,'Model inputs'!U35,'Model inputs'!V35,'Model inputs'!W35,'Model inputs'!X35,'Model inputs'!Y35,'Model inputs'!Z35,'Model inputs'!B35) -> 46357
A8: Peak founder funding | B8: =MAX('Base and upside comparison'!B13,'Base and upside comparison'!D13,'Base and upside comparison'!F13,'Base and upside comparison'!H13,'Base and upside comparison'!J13,'Base and upside comparison'!L13,'Base and upside comparison'!N13,'Base and upside comparison'!P13,'Base and upside comparison'!R13,'Base and upside comparison'!T13,'Base and upside comparison'!V13,'Base and upside comparison'!X13,'Base and upside comparison'!Z13,'Base and upside comparison'!AB13,'Base and upside comparison'!AD13,'Base and upside comparison'!AF13,'Base and upside comparison'!AH13,'Base and upside comparison'!AJ13,'Base and upside comparison'!AL13,'Base and upside comparison'!AN13,'Base and upside comparison'!AP13,'Base and upside comparison'!AR13,'Base and upside comparison'!AT13,'Base and upside comparison'!AV13) -> 144
A9: Cumulative cash low point | B9: =MIN('Base and upside comparison'!B12,'Base and upside comparison'!D12,'Base and upside comparison'!F12,'Base and upside comparison'!H12,'Base and upside comparison'!J12,'Base and upside comparison'!L12,'Base and upside comparison'!N12,'Base and upside comparison'!P12,'Base and upside comparison'!R12,'Base and upside comparison'!T12,'Base and upside comparison'!V12,'Base and upside comparison'!X12,'Base and upside comparison'!Z12,'Base and upside comparison'!AB12,'Base and upside comparison'!AD12,'Base and upside comparison'!AF12,'Base and upside comparison'!AH12,'Base and upside comparison'!AJ12,'Base and upside comparison'!AL12,'Base and upside comparison'!AN12,'Base and upside comparison'!AP12,'Base and upside comparison'!AR12,'Base and upside comparison'!AT12,'Base and upside comparison'!AV12) -> -144
A10: Month-24 paid repositories | B10: =IF('Base and upside comparison'!AV5="","",'Base and upside comparison'!AV5) -> 108.03848
A11: Month-24 monthly revenue | B11: =IF('Base and upside comparison'!AV6="","",'Base and upside comparison'!AV6) -> 5293.8856
A12: Month-24 ARR | B12: =IF('Model inputs'!B6="","",'Model inputs'!B6) -> 63526.628
A13: Month-24 unfunded cash | B13: =IF('Base and upside comparison'!AV12="","",'Base and upside comparison'!AV12) -> 36559.209
A14: Baseline Team gross margin | B14: =1-('Model inputs'!C63*'Model inputs'!C62+'Model inputs'!C8*('Model inputs'!C9+'Model inputs'!C7)+'Model inputs'!C56)/'Model inputs'!C59-'Model inputs'!C54 -> 0.95510204
A15: Team break-even repositories | B15: =CEILING((SUM('Model inputs'!C28)*(1+'Model inputs'!C55)+SUM('Model inputs'!C39,'Model inputs'!C40,'Model inputs'!C41)+'Model inputs'!C37)/('Model inputs'!C59*(1-'Model inputs'!C54)-('Model inputs'!C63*'Model inputs'!C62+'Model inputs'!C8*('Model inputs'!C9+'Model inputs'!C7)+'Model inputs'!C56)),1) -> 7

Sheet Base and upside comparison
A1: Base and upside comparison
A2: Upshift — Business Plan · Main Scenario
A4: Variable / dimension | B4: 2026-10 | C4: 2026-10 > Upshift — Upside | D4: 2026-11 | E4: 2026-11 > Upshift — Upside | F4: 2026-12 | G4: 2026-12 > Upshift — Upside | H4: 2027-01 | I4: 2027-01 > Upshift — Upside | J4: 2027-02 | K4: 2027-02 > Upshift — Upside | L4: 2027-03 | M4: 2027-03 > Upshift — Upside | N4: 2027-04 | O4: 2027-04 > Upshift — Upside | P4: 2027-05 | Q4: 2027-05 > Upshift — Upside | R4: 2027-06 | S4: 2027-06 > Upshift — Upside | T4: 2027-07 | U4: 2027-07 > Upshift — Upside | V4: 2027-08 | W4: 2027-08 > Upshift — Upside | X4: 2027-09 | Y4: 2027-09 > Upshift — Upside | Z4: 2027-10 | AA4: 2027-10 > Upshift — Upside | AB4: 2027-11 | AC4: 2027-11 > Upshift — Upside | AD4: 2027-12 | AE4: 2027-12 > Upshift — Upside | AF4: 2028-01 | AG4: 2028-01 > Upshift — Upside | AH4: 2028-02 | AI4: 2028-02 > Upshift — Upside | AJ4: 2028-03 | AK4: 2028-03 > Upshift — Upside | AL4: 2028-04 | AM4: 2028-04 > Upshift — Upside | AN4: 2028-05 | AO4: 2028-05 > Upshift — Upside | AP4: 2028-06 | AQ4: 2028-06 > Upshift — Upside | AR4: 2028-07 | AS4: 2028-07 > Upshift — Upside | AT4: 2028-08 | AU4: 2028-08 > Upshift — Upside | AV4: 2028-09 | AW4: 2028-09 > Upshift — Upside
A5: Paid repositories | B5: ='Model inputs'!D46+'Model inputs'!D44-'Model inputs'!D14 -> 3.3333333 | C5: ='Model inputs'!D47+'Model inputs'!D45-'Model inputs'!D15 -> 8.3333333 | D5: ='Model inputs'!E46+'Model inputs'!E44-'Model inputs'!E14 -> 6.6666667 | E5: ='Model inputs'!E47+'Model inputs'!E45-'Model inputs'!E15 -> 16.666667 | F5: ='Model inputs'!F46+'Model inputs'!F44-'Model inputs'!F14 -> 10 | G5: ='Model inputs'!F47+'Model inputs'!F45-'Model inputs'!F15 -> 25 | H5: ='Model inputs'!G46+'Model inputs'!G44-'Model inputs'!G14 -> 11.2 | I5: ='Model inputs'!G47+'Model inputs'!G45-'Model inputs'!G15 -> 30.5 | J5: ='Model inputs'!H46+'Model inputs'!H44-'Model inputs'!H14 -> 12.544 | K5: ='Model inputs'!H47+'Model inputs'!H45-'Model inputs'!H15 -> 37.21 | L5: ='Model inputs'!I46+'Model inputs'!I44-'Model inputs'!I14 -> 14.04928 | M5: ='Model inputs'!I47+'Model inputs'!I45-'Model inputs'!I15 -> 45.3962 | N5: ='Model inputs'!J46+'Model inputs'!J44-'Model inputs'!J14 -> 15.735194 | O5: ='Model inputs'!J47+'Model inputs'!J45-'Model inputs'!J15 -> 55.383364 | P5: ='Model inputs'!K46+'Model inputs'!K44-'Model inputs'!K14 -> 17.623417 | Q5: ='Model inputs'!K47+'Model inputs'!K45-'Model inputs'!K15 -> 67.567704 | R5: ='Model inputs'!L46+'Model inputs'!L44-'Model inputs'!L14 -> 19.738227 | S5: ='Model inputs'!L47+'Model inputs'!L45-'Model inputs'!L15 -> 82.432599 | T5: ='Model inputs'!M46+'Model inputs'!M44-'Model inputs'!M14 -> 22.106814 | U5: ='Model inputs'!M47+'Model inputs'!M45-'Model inputs'!M15 -> 100.56777 | V5: ='Model inputs'!N46+'Model inputs'!N44-'Model inputs'!N14 -> 24.759632 | W5: ='Model inputs'!N47+'Model inputs'!N45-'Model inputs'!N15 -> 122.69268 | X5: ='Model inputs'!O46+'Model inputs'!O44-'Model inputs'!O14 -> 27.730788 | Y5: ='Model inputs'!O47+'Model inputs'!O45-'Model inputs'!O15 -> 149.68507 | Z5: ='Model inputs'!P46+'Model inputs'!P44-'Model inputs'!P14 -> 31.058482 | AA5: ='Model inputs'!P47+'Model inputs'!P45-'Model inputs'!P15 -> 182.61579 | AB5: ='Model inputs'!Q46+'Model inputs'!Q44-'Model inputs'!Q14 -> 34.7855 | AC5: ='Model inputs'!Q47+'Model inputs'!Q45-'Model inputs'!Q15 -> 222.79126 | AD5: ='Model inputs'!R46+'Model inputs'!R44-'Model inputs'!R14 -> 38.95976 | AE5: ='Model inputs'!R47+'Model inputs'!R45-'Model inputs'!R15 -> 271.80533 | AF5: ='Model inputs'!S46+'Model inputs'!S44-'Model inputs'!S14 -> 43.634931 | AG5: ='Model inputs'!S47+'Model inputs'!S45-'Model inputs'!S15 -> 331.60251 | AH5: ='Model inputs'!T46+'Model inputs'!T44-'Model inputs'!T14 -> 48.871123 | AI5: ='Model inputs'!T47+'Model inputs'!T45-'Model inputs'!T15 -> 404.55506 | AJ5: ='Model inputs'!U46+'Model inputs'!U44-'Model inputs'!U14 -> 54.735658 | AK5: ='Model inputs'!U47+'Model inputs'!U45-'Model inputs'!U15 -> 493.55717 | AL5: ='Model inputs'!V46+'Model inputs'!V44-'Model inputs'!V14 -> 61.303937 | AM5: ='Model inputs'!V47+'Model inputs'!V45-'Model inputs'!V15 -> 602.13975 | AN5: ='Model inputs'!W46+'Model inputs'!W44-'Model inputs'!W14 -> 68.660409 | AO5: ='Model inputs'!W47+'Model inputs'!W45-'Model inputs'!W15 -> 734.6105 | AP5: ='Model inputs'!X46+'Model inputs'!X44-'Model inputs'!X14 -> 76.899658 | AQ5: ='Model inputs'!X47+'Model inputs'!X45-'Model inputs'!X15 -> 896.22481 | AR5: ='Model inputs'!Y46+'Model inputs'!Y44-'Model inputs'!Y14 -> 86.127617 | AS5: ='Model inputs'!Y47+'Model inputs'!Y45-'Model inputs'!Y15 -> 1093.3943 | AT5: ='Model inputs'!Z46+'Model inputs'!Z44-'Model inputs'!Z14 -> 96.462931 | AU5: ='Model inputs'!Z47+'Model inputs'!Z45-'Model inputs'!Z15 -> 1333.941 | AV5: ='Model inputs'!B46+'Model inputs'!B44-'Model inputs'!B14 -> 108.03848 | AW5: ='Model inputs'!B47+'Model inputs'!B45-'Model inputs'!B15 -> 1627.408
A6: Revenue | B6: ='Model inputs'!D66+'Model inputs'!D49 -> 163.33333 | C6: ='Model inputs'!D67+'Model inputs'!D50 -> 408.33333 | D6: ='Model inputs'!E66+'Model inputs'!E49 -> 326.66667 | E6: ='Model inputs'!E67+'Model inputs'!E50 -> 816.66667 | F6: ='Model inputs'!F66+'Model inputs'!F49 -> 490 | G6: ='Model inputs'!F67+'Model inputs'!F50 -> 1225 | H6: ='Model inputs'!G66+'Model inputs'!G49 -> 548.8 | I6: ='Model inputs'!G67+'Model inputs'!G50 -> 1494.5 | J6: ='Model inputs'!H66+'Model inputs'!H49 -> 614.656 | K6: ='Model inputs'!H67+'Model inputs'!H50 -> 1823.29 | L6: ='Model inputs'!I66+'Model inputs'!I49 -> 688.41472 | M6: ='Model inputs'!I67+'Model inputs'!I50 -> 2224.4138 | N6: ='Model inputs'!J66+'Model inputs'!J49 -> 771.02449 | O6: ='Model inputs'!J67+'Model inputs'!J50 -> 2713.7848 | P6: ='Model inputs'!K66+'Model inputs'!K49 -> 863.54742 | Q6: ='Model inputs'!K67+'Model inputs'!K50 -> 3310.8175 | R6: ='Model inputs'!L66+'Model inputs'!L49 -> 967.17312 | S6: ='Model inputs'!L67+'Model inputs'!L50 -> 4039.1973 | T6: ='Model inputs'!M66+'Model inputs'!M49 -> 1083.2339 | U6: ='Model inputs'!M67+'Model inputs'!M50 -> 4927.8208 | V6: ='Model inputs'!N66+'Model inputs'!N49 -> 1213.222 | W6: ='Model inputs'!N67+'Model inputs'!N50 -> 6011.9413 | X6: ='Model inputs'!O66+'Model inputs'!O49 -> 1358.8086 | Y6: ='Model inputs'!O67+'Model inputs'!O50 -> 7334.5684 | Z6: ='Model inputs'!P66+'Model inputs'!P49 -> 1521.8656 | AA6: ='Model inputs'!P67+'Model inputs'!P50 -> 8948.1735 | AB6: ='Model inputs'!Q66+'Model inputs'!Q49 -> 1704.4895 | AC6: ='Model inputs'!Q67+'Model inputs'!Q50 -> 10916.772 | AD6: ='Model inputs'!R66+'Model inputs'!R49 -> 1909.0282 | AE6: ='Model inputs'!R67+'Model inputs'!R50 -> 13318.461 | AF6: ='Model inputs'!S66+'Model inputs'!S49 -> 2138.1116 | AG6: ='Model inputs'!S67+'Model inputs'!S50 -> 16248.523 | AH6: ='Model inputs'!T66+'Model inputs'!T49 -> 2394.685 | AI6: ='Model inputs'!T67+'Model inputs'!T50 -> 19823.198 | AJ6: ='Model inputs'!U66+'Model inputs'!U49 -> 2682.0472 | AK6: ='Model inputs'!U67+'Model inputs'!U50 -> 24184.302 | AL6: ='Model inputs'!V66+'Model inputs'!V49 -> 3003.8929 | AM6: ='Model inputs'!V67+'Model inputs'!V50 -> 29504.848 | AN6: ='Model inputs'!W66+'Model inputs'!W49 -> 3364.36 | AO6: ='Model inputs'!W67+'Model inputs'!W50 -> 35995.914 | AP6: ='Model inputs'!X66+'Model inputs'!X49 -> 3768.0832 | AQ6: ='Model inputs'!X67+'Model inputs'!X50 -> 43915.016 | AR6: ='Model inputs'!Y66+'Model inputs'!Y49 -> 4220.2532 | AS6: ='Model inputs'!Y67+'Model inputs'!Y50 -> 53576.319 | AT6: ='Model inputs'!Z66+'Model inputs'!Z49 -> 4726.6836 | AU6: ='Model inputs'!Z67+'Model inputs'!Z50 -> 65363.109 | AV6: ='Model inputs'!B66+'Model inputs'!B49 -> 5293.8856 | AW6: ='Model inputs'!B67+'Model inputs'!B50 -> 79742.993
A7: Cost of revenue | B7: ='Model inputs'!D33+'Model inputs'!D17+'Model inputs'!D19+'Model inputs'!D52 -> 7.3333333 | C7: ='Model inputs'!D34+'Model inputs'!D18+'Model inputs'!D20+'Model inputs'!D53 -> 18.333333 | D7: ='Model inputs'!E33+'Model inputs'!E17+'Model inputs'!E19+'Model inputs'!E52 -> 14.666667 | E7: ='Model inputs'!E34+'Model inputs'!E18+'Model inputs'!E20+'Model inputs'!E53 -> 36.666667 | F7: ='Model inputs'!F33+'Model inputs'!F17+'Model inputs'!F19+'Model inputs'!F52 -> 22 | G7: ='Model inputs'!F34+'Model inputs'!F18+'Model inputs'!F20+'Model inputs'!F53 -> 55 | H7: ='Model inputs'!G33+'Model inputs'!G17+'Model inputs'!G19+'Model inputs'!G52 -> 24.64 | I7: ='Model inputs'!G34+'Model inputs'!G18+'Model inputs'!G20+'Model inputs'!G53 -> 67.1 | J7: ='Model inputs'!H33+'Model inputs'!H17+'Model inputs'!H19+'Model inputs'!H52 -> 27.5968 | K7: ='Model inputs'!H34+'Model inputs'!H18+'Model inputs'!H20+'Model inputs'!H53 -> 81.862 | L7: ='Model inputs'!I33+'Model inputs'!I17+'Model inputs'!I19+'Model inputs'!I52 -> 30.908416 | M7: ='Model inputs'!I34+'Model inputs'!I18+'Model inputs'!I20+'Model inputs'!I53 -> 99.87164 | N7: ='Model inputs'!J33+'Model inputs'!J17+'Model inputs'!J19+'Model inputs'!J52 -> 34.617426 | O7: ='Model inputs'!J34+'Model inputs'!J18+'Model inputs'!J20+'Model inputs'!J53 -> 121.8434 | P7: ='Model inputs'!K33+'Model inputs'!K17+'Model inputs'!K19+'Model inputs'!K52 -> 38.771517 | Q7: ='Model inputs'!K34+'Model inputs'!K18+'Model inputs'!K20+'Model inputs'!K53 -> 148.64895 | R7: ='Model inputs'!L33+'Model inputs'!L17+'Model inputs'!L19+'Model inputs'!L52 -> 43.424099 | S7: ='Model inputs'!L34+'Model inputs'!L18+'Model inputs'!L20+'Model inputs'!L53 -> 181.35172 | T7: ='Model inputs'!M33+'Model inputs'!M17+'Model inputs'!M19+'Model inputs'!M52 -> 48.634991 | U7: ='Model inputs'!M34+'Model inputs'!M18+'Model inputs'!M20+'Model inputs'!M53 -> 221.2491 | V7: ='Model inputs'!N33+'Model inputs'!N17+'Model inputs'!N19+'Model inputs'!N52 -> 54.47119 | W7: ='Model inputs'!N34+'Model inputs'!N18+'Model inputs'!N20+'Model inputs'!N53 -> 269.9239 | X7: ='Model inputs'!O33+'Model inputs'!O17+'Model inputs'!O19+'Model inputs'!O52 -> 61.007733 | Y7: ='Model inputs'!O34+'Model inputs'!O18+'Model inputs'!O20+'Model inputs'!O53 -> 329.30715 | Z7: ='Model inputs'!P33+'Model inputs'!P17+'Model inputs'!P19+'Model inputs'!P52 -> 68.328661 | AA7: ='Model inputs'!P34+'Model inputs'!P18+'Model inputs'!P20+'Model inputs'!P53 -> 401.75473 | AB7: ='Model inputs'!Q33+'Model inputs'!Q17+'Model inputs'!Q19+'Model inputs'!Q52 -> 76.5281 | AC7: ='Model inputs'!Q34+'Model inputs'!Q18+'Model inputs'!Q20+'Model inputs'!Q53 -> 490.14077 | AD7: ='Model inputs'!R33+'Model inputs'!R17+'Model inputs'!R19+'Model inputs'!R52 -> 85.711472 | AE7: ='Model inputs'!R34+'Model inputs'!R18+'Model inputs'!R20+'Model inputs'!R53 -> 597.97174 | AF7: ='Model inputs'!S33+'Model inputs'!S17+'Model inputs'!S19+'Model inputs'!S52 -> 95.996848 | AG7: ='Model inputs'!S34+'Model inputs'!S18+'Model inputs'!S20+'Model inputs'!S53 -> 729.52552 | AH7: ='Model inputs'!T33+'Model inputs'!T17+'Model inputs'!T19+'Model inputs'!T52 -> 107.51647 | AI7: ='Model inputs'!T34+'Model inputs'!T18+'Model inputs'!T20+'Model inputs'!T53 -> 890.02113 | AJ7: ='Model inputs'!U33+'Model inputs'!U17+'Model inputs'!U19+'Model inputs'!U52 -> 120.41845 | AK7: ='Model inputs'!U34+'Model inputs'!U18+'Model inputs'!U20+'Model inputs'!U53 -> 1085.8258 | AL7: ='Model inputs'!V33+'Model inputs'!V17+'Model inputs'!V19+'Model inputs'!V52 -> 134.86866 | AM7: ='Model inputs'!V34+'Model inputs'!V18+'Model inputs'!V20+'Model inputs'!V53 -> 1324.7075 | AN7: ='Model inputs'!W33+'Model inputs'!W17+'Model inputs'!W19+'Model inputs'!W52 -> 151.0529 | AO7: ='Model inputs'!W34+'Model inputs'!W18+'Model inputs'!W20+'Model inputs'!W53 -> 1616.1431 | AP7: ='Model inputs'!X33+'Model inputs'!X17+'Model inputs'!X19+'Model inputs'!X52 -> 169.17925 | AQ7: ='Model inputs'!X34+'Model inputs'!X18+'Model inputs'!X20+'Model inputs'!X53 -> 1971.6946 | AR7: ='Model inputs'!Y33+'Model inputs'!Y17+'Model inputs'!Y19+'Model inputs'!Y52 -> 189.48076 | AS7: ='Model inputs'!Y34+'Model inputs'!Y18+'Model inputs'!Y20+'Model inputs'!Y53 -> 2405.4674 | AT7: ='Model inputs'!Z33+'Model inputs'!Z17+'Model inputs'!Z19+'Model inputs'!Z52 -> 212.21845 | AU7: ='Model inputs'!Z34+'Model inputs'!Z18+'Model inputs'!Z20+'Model inputs'!Z53 -> 2934.6702 | AV7: ='Model inputs'!B33+'Model inputs'!B17+'Model inputs'!B19+'Model inputs'!B52 -> 237.68466 | AW7: ='Model inputs'!B34+'Model inputs'!B18+'Model inputs'!B20+'Model inputs'!B53 -> 3580.2977
A8: Gross margin | B8: =IFERROR('Model inputs'!D31/'Base and upside comparison'!B6,"") -> 0.95510204 | C8: =IFERROR('Model inputs'!D32/'Base and upside comparison'!C6,"") -> 0.95510204 | D8: =IFERROR('Model inputs'!E31/'Base and upside comparison'!D6,"") -> 0.95510204 | E8: =IFERROR('Model inputs'!E32/'Base and upside comparison'!E6,"") -> 0.95510204 | F8: =IFERROR('Model inputs'!F31/'Base and upside comparison'!F6,"") -> 0.95510204 | G8: =IFERROR('Model inputs'!F32/'Base and upside comparison'!G6,"") -> 0.95510204 | H8: =IFERROR('Model inputs'!G31/'Base and upside comparison'!H6,"") -> 0.95510204 | I8: =IFERROR('Model inputs'!G32/'Base and upside comparison'!I6,"") -> 0.95510204 | J8: =IFERROR('Model inputs'!H31/'Base and upside comparison'!J6,"") -> 0.95510204 | K8: =IFERROR('Model inputs'!H32/'Base and upside comparison'!K6,"") -> 0.95510204 | L8: =IFERROR('Model inputs'!I31/'Base and upside comparison'!L6,"") -> 0.95510204 | M8: =IFERROR('Model inputs'!I32/'Base and upside comparison'!M6,"") -> 0.95510204 | N8: =IFERROR('Model inputs'!J31/'Base and upside comparison'!N6,"") -> 0.95510204 | O8: =IFERROR('Model inputs'!J32/'Base and upside comparison'!O6,"") -> 0.95510204 | P8: =IFERROR('Model inputs'!K31/'Base and upside comparison'!P6,"") -> 0.95510204 | Q8: =IFERROR('Model inputs'!K32/'Base and upside comparison'!Q6,"") -> 0.95510204 | R8: =IFERROR('Model inputs'!L31/'Base and upside comparison'!R6,"") -> 0.95510204 | S8: =IFERROR('Model inputs'!L32/'Base and upside comparison'!S6,"") -> 0.95510204 | T8: =IFERROR('Model inputs'!M31/'Base and upside comparison'!T6,"") -> 0.95510204 | U8: =IFERROR('Model inputs'!M32/'Base and upside comparison'!U6,"") -> 0.95510204 | V8: =IFERROR('Model inputs'!N31/'Base and upside comparison'!V6,"") -> 0.95510204 | W8: =IFERROR('Model inputs'!N32/'Base and upside comparison'!W6,"") -> 0.95510204 | X8: =IFERROR('Model inputs'!O31/'Base and upside comparison'!X6,"") -> 0.95510204 | Y8: =IFERROR('Model inputs'!O32/'Base and upside comparison'!Y6,"") -> 0.95510204 | Z8: =IFERROR('Model inputs'!P31/'Base and upside comparison'!Z6,"") -> 0.95510204 | AA8: =IFERROR('Model inputs'!P32/'Base and upside comparison'!AA6,"") -> 0.95510204 | AB8: =IFERROR('Model inputs'!Q31/'Base and upside comparison'!AB6,"") -> 0.95510204 | AC8: =IFERROR('Model inputs'!Q32/'Base and upside comparison'!AC6,"") -> 0.95510204 | AD8: =IFERROR('Model inputs'!R31/'Base and upside comparison'!AD6,"") -> 0.95510204 | AE8: =IFERROR('Model inputs'!R32/'Base and upside comparison'!AE6,"") -> 0.95510204 | AF8: =IFERROR('Model inputs'!S31/'Base and upside comparison'!AF6,"") -> 0.95510204 | AG8: =IFERROR('Model inputs'!S32/'Base and upside comparison'!AG6,"") -> 0.95510204 | AH8: =IFERROR('Model inputs'!T31/'Base and upside comparison'!AH6,"") -> 0.95510204 | AI8: =IFERROR('Model inputs'!T32/'Base and upside comparison'!AI6,"") -> 0.95510204 | AJ8: =IFERROR('Model inputs'!U31/'Base and upside comparison'!AJ6,"") -> 0.95510204 | AK8: =IFERROR('Model inputs'!U32/'Base and upside comparison'!AK6,"") -> 0.95510204 | AL8: =IFERROR('Model inputs'!V31/'Base and upside comparison'!AL6,"") -> 0.95510204 | AM8: =IFERROR('Model inputs'!V32/'Base and upside comparison'!AM6,"") -> 0.95510204 | AN8: =IFERROR('Model inputs'!W31/'Base and upside comparison'!AN6,"") -> 0.95510204 | AO8: =IFERROR('Model inputs'!W32/'Base and upside comparison'!AO6,"") -> 0.95510204 | AP8: =IFERROR('Model inputs'!X31/'Base and upside comparison'!AP6,"") -> 0.95510204 | AQ8: =IFERROR('Model inputs'!X32/'Base and upside comparison'!AQ6,"") -> 0.95510204 | AR8: =IFERROR('Model inputs'!Y31/'Base and upside comparison'!AR6,"") -> 0.95510204 | AS8: =IFERROR('Model inputs'!Y32/'Base and upside comparison'!AS6,"") -> 0.95510204 | AT8: =IFERROR('Model inputs'!Z31/'Base and upside comparison'!AT6,"") -> 0.95510204 | AU8: =IFERROR('Model inputs'!Z32/'Base and upside comparison'!AU6,"") -> 0.95510204 | AV8: =IFERROR('Model inputs'!B31/'Base and upside comparison'!AV6,"") -> 0.95510204 | AW8: =IFERROR('Model inputs'!B32/'Base and upside comparison'!AW6,"") -> 0.95510204
A9: Operating costs | B9: ='Model inputs'!D29+'Model inputs'!D21 -> 300 | C9: ='Model inputs'!D30+'Model inputs'!D22 -> 300 | D9: ='Model inputs'!E29+'Model inputs'!E21 -> 300 | E9: ='Model inputs'!E30+'Model inputs'!E22 -> 300 | F9: ='Model inputs'!F29+'Model inputs'!F21 -> 300 | G9: ='Model inputs'!F30+'Model inputs'!F22 -> 300 | H9: ='Model inputs'!G29+'Model inputs'!G21 -> 300 | I9: ='Model inputs'!G30+'Model inputs'!G22 -> 300 | J9: ='Model inputs'!H29+'Model inputs'!H21 -> 300 | K9: ='Model inputs'!H30+'Model inputs'!H22 -> 300 | L9: ='Model inputs'!I29+'Model inputs'!I21 -> 300 | M9: ='Model inputs'!I30+'Model inputs'!I22 -> 300 | N9: ='Model inputs'!J29+'Model inputs'!J21 -> 300 | O9: ='Model inputs'!J30+'Model inputs'!J22 -> 300 | P9: ='Model inputs'!K29+'Model inputs'!K21 -> 300 | Q9: ='Model inputs'!K30+'Model inputs'!K22 -> 300 | R9: ='Model inputs'!L29+'Model inputs'!L21 -> 300 | S9: ='Model inputs'!L30+'Model inputs'!L22 -> 300 | T9: ='Model inputs'!M29+'Model inputs'!M21 -> 300 | U9: ='Model inputs'!M30+'Model inputs'!M22 -> 300 | V9: ='Model inputs'!N29+'Model inputs'!N21 -> 300 | W9: ='Model inputs'!N30+'Model inputs'!N22 -> 300 | X9: ='Model inputs'!O29+'Model inputs'!O21 -> 300 | Y9: ='Model inputs'!O30+'Model inputs'!O22 -> 300 | Z9: ='Model inputs'!P29+'Model inputs'!P21 -> 300 | AA9: ='Model inputs'!P30+'Model inputs'!P22 -> 300 | AB9: ='Model inputs'!Q29+'Model inputs'!Q21 -> 300 | AC9: ='Model inputs'!Q30+'Model inputs'!Q22 -> 300 | AD9: ='Model inputs'!R29+'Model inputs'!R21 -> 300 | AE9: ='Model inputs'!R30+'Model inputs'!R22 -> 300 | AF9: ='Model inputs'!S29+'Model inputs'!S21 -> 300 | AG9: ='Model inputs'!S30+'Model inputs'!S22 -> 300 | AH9: ='Model inputs'!T29+'Model inputs'!T21 -> 300 | AI9: ='Model inputs'!T30+'Model inputs'!T22 -> 300 | AJ9: ='Model inputs'!U29+'Model inputs'!U21 -> 300 | AK9: ='Model inputs'!U30+'Model inputs'!U22 -> 300 | AL9: ='Model inputs'!V29+'Model inputs'!V21 -> 300 | AM9: ='Model inputs'!V30+'Model inputs'!V22 -> 300 | AN9: ='Model inputs'!W29+'Model inputs'!W21 -> 300 | AO9: ='Model inputs'!W30+'Model inputs'!W22 -> 300 | AP9: ='Model inputs'!X29+'Model inputs'!X21 -> 300 | AQ9: ='Model inputs'!X30+'Model inputs'!X22 -> 300 | AR9: ='Model inputs'!Y29+'Model inputs'!Y21 -> 300 | AS9: ='Model inputs'!Y30+'Model inputs'!Y22 -> 300 | AT9: ='Model inputs'!Z29+'Model inputs'!Z21 -> 300 | AU9: ='Model inputs'!Z30+'Model inputs'!Z22 -> 300 | AV9: ='Model inputs'!B29+'Model inputs'!B21 -> 300 | AW9: ='Model inputs'!B30+'Model inputs'!B22 -> 300
A10: Operating profit | B10: ='Model inputs'!D31-'Base and upside comparison'!B9 -> -144 | C10: ='Model inputs'!D32-'Base and upside comparison'!C9 -> 90 | D10: ='Model inputs'!E31-'Base and upside comparison'!D9 -> 12 | E10: ='Model inputs'!E32-'Base and upside comparison'!E9 -> 480 | F10: ='Model inputs'!F31-'Base and upside comparison'!F9 -> 168 | G10: ='Model inputs'!F32-'Base and upside comparison'!G9 -> 870 | H10: ='Model inputs'!G31-'Base and upside comparison'!H9 -> 224.16 | I10: ='Model inputs'!G32-'Base and upside comparison'!I9 -> 1127.4 | J10: ='Model inputs'!H31-'Base and upside comparison'!J9 -> 287.0592 | K10: ='Model inputs'!H32-'Base and upside comparison'!K9 -> 1441.428 | L10: ='Model inputs'!I31-'Base and upside comparison'!L9 -> 357.5063 | M10: ='Model inputs'!I32-'Base and upside comparison'!M9 -> 1824.5422 | N10: ='Model inputs'!J31-'Base and upside comparison'!N9 -> 436.40706 | O10: ='Model inputs'!J32-'Base and upside comparison'!O9 -> 2291.9414 | P10: ='Model inputs'!K31-'Base and upside comparison'!P9 -> 524.77591 | Q10: ='Model inputs'!K32-'Base and upside comparison'!Q9 -> 2862.1686 | R10: ='Model inputs'!L31-'Base and upside comparison'!R9 -> 623.74902 | S10: ='Model inputs'!L32-'Base and upside comparison'!S9 -> 3557.8456 | T10: ='Model inputs'!M31-'Base and upside comparison'!T9 -> 734.5989 | U10: ='Model inputs'!M32-'Base and upside comparison'!U9 -> 4406.5717 | V10: ='Model inputs'!N31-'Base and upside comparison'!V9 -> 858.75077 | W10: ='Model inputs'!N32-'Base and upside comparison'!W9 -> 5442.0174 | X10: ='Model inputs'!O31-'Base and upside comparison'!X9 -> 997.80086 | Y10: ='Model inputs'!O32-'Base and upside comparison'!Y9 -> 6705.2613 | Z10: ='Model inputs'!P31-'Base and upside comparison'!Z9 -> 1153.537 | AA10: ='Model inputs'!P32-'Base and upside comparison'!AA9 -> 8246.4188 | AB10: ='Model inputs'!Q31-'Base and upside comparison'!AB9 -> 1327.9614 | AC10: ='Model inputs'!Q32-'Base and upside comparison'!AC9 -> 10126.631 | AD10: ='Model inputs'!R31-'Base and upside comparison'!AD9 -> 1523.3168 | AE10: ='Model inputs'!R32-'Base and upside comparison'!AE9 -> 12420.49 | AF10: ='Model inputs'!S31-'Base and upside comparison'!AF9 -> 1742.1148 | AG10: ='Model inputs'!S32-'Base and upside comparison'!AG9 -> 15218.997 | AH10: ='Model inputs'!T31-'Base and upside comparison'!AH9 -> 1987.1685 | AI10: ='Model inputs'!T32-'Base and upside comparison'!AI9 -> 18633.177 | AJ10: ='Model inputs'!U31-'Base and upside comparison'!AJ9 -> 2261.6288 | AK10: ='Model inputs'!U32-'Base and upside comparison'!AK9 -> 22798.476 | AL10: ='Model inputs'!V31-'Base and upside comparison'!AL9 -> 2569.0242 | AM10: ='Model inputs'!V32-'Base and upside comparison'!AM9 -> 27880.14 | AN10: ='Model inputs'!W31-'Base and upside comparison'!AN9 -> 2913.3071 | AO10: ='Model inputs'!W32-'Base and upside comparison'!AO9 -> 34079.771 | AP10: ='Model inputs'!X31-'Base and upside comparison'!AP9 -> 3298.904 | AQ10: ='Model inputs'!X32-'Base and upside comparison'!AQ9 -> 41643.321 | AR10: ='Model inputs'!Y31-'Base and upside comparison'!AR9 -> 3730.7725 | AS10: ='Model inputs'!Y32-'Base and upside comparison'!AS9 -> 50870.852 | AT10: ='Model inputs'!Z31-'Base and upside comparison'!AT9 -> 4214.4652 | AU10: ='Model inputs'!Z32-'Base and upside comparison'!AU9 -> 62128.439 | AV10: ='Model inputs'!B31-'Base and upside comparison'!AV9 -> 4756.201 | AW10: ='Model inputs'!B32-'Base and upside comparison'!AW9 -> 75862.696
A11: Monthly burn | B11: =MAX(0,-'Model inputs'!D42) -> 144 | C11: =MAX(0,-'Model inputs'!D43) -> 0 | D11: =MAX(0,-'Model inputs'!E42) -> 0 | E11: =MAX(0,-'Model inputs'!E43) -> 0 | F11: =MAX(0,-'Model inputs'!F42) -> 0 | G11: =MAX(0,-'Model inputs'!F43) -> 0 | H11: =MAX(0,-'Model inputs'!G42) -> 0 | I11: =MAX(0,-'Model inputs'!G43) -> 0 | J11: =MAX(0,-'Model inputs'!H42) -> 0 | K11: =MAX(0,-'Model inputs'!H43) -> 0 | L11: =MAX(0,-'Model inputs'!I42) -> 0 | M11: =MAX(0,-'Model inputs'!I43) -> 0 | N11: =MAX(0,-'Model inputs'!J42) -> 0 | O11: =MAX(0,-'Model inputs'!J43) -> 0 | P11: =MAX(0,-'Model inputs'!K42) -> 0 | Q11: =MAX(0,-'Model inputs'!K43) -> 0 | R11: =MAX(0,-'Model inputs'!L42) -> 0 | S11: =MAX(0,-'Model inputs'!L43) -> 0 | T11: =MAX(0,-'Model inputs'!M42) -> 0 | U11: =MAX(0,-'Model inputs'!M43) -> 0 | V11: =MAX(0,-'Model inputs'!N42) -> 0 | W11: =MAX(0,-'Model inputs'!N43) -> 0 | X11: =MAX(0,-'Model inputs'!O42) -> 0 | Y11: =MAX(0,-'Model inputs'!O43) -> 0 | Z11: =MAX(0,-'Model inputs'!P42) -> 0 | AA11: =MAX(0,-'Model inputs'!P43) -> 0 | AB11: =MAX(0,-'Model inputs'!Q42) -> 0 | AC11: =MAX(0,-'Model inputs'!Q43) -> 0 | AD11: =MAX(0,-'Model inputs'!R42) -> 0 | AE11: =MAX(0,-'Model inputs'!R43) -> 0 | AF11: =MAX(0,-'Model inputs'!S42) -> 0 | AG11: =MAX(0,-'Model inputs'!S43) -> 0 | AH11: =MAX(0,-'Model inputs'!T42) -> 0 | AI11: =MAX(0,-'Model inputs'!T43) -> 0 | AJ11: =MAX(0,-'Model inputs'!U42) -> 0 | AK11: =MAX(0,-'Model inputs'!U43) -> 0 | AL11: =MAX(0,-'Model inputs'!V42) -> 0 | AM11: =MAX(0,-'Model inputs'!V43) -> 0 | AN11: =MAX(0,-'Model inputs'!W42) -> 0 | AO11: =MAX(0,-'Model inputs'!W43) -> 0 | AP11: =MAX(0,-'Model inputs'!X42) -> 0 | AQ11: =MAX(0,-'Model inputs'!X43) -> 0 | AR11: =MAX(0,-'Model inputs'!Y42) -> 0 | AS11: =MAX(0,-'Model inputs'!Y43) -> 0 | AT11: =MAX(0,-'Model inputs'!Z42) -> 0 | AU11: =MAX(0,-'Model inputs'!Z43) -> 0 | AV11: =MAX(0,-'Model inputs'!B42) -> 0 | AW11: =MAX(0,-'Model inputs'!B43) -> 0
